<?xml version="1.0"?>
<robot name="elevator">

  <!-- =========================
       Static elevator body
       ========================= -->
  <link name="cabin_link">
    <visual>
      <origin xyz="0 0 0" rpy="0 0 0"/>
      <geometry>
        <mesh filename="static_elevator.dae" scale="1 1 1"/>
      </geometry>
    </visual>

    <collision>
      <origin xyz="0 0 0" rpy="0 0 0"/>
      <geometry>
        <box size="4.2356 0.2952 3.2904"/>
      </geometry>
    </collision>

    <inertial>
      <origin xyz="0 0 0" rpy="0 0 0"/>
      <mass value="50.0"/>
      <inertia ixx="10" ixy="0" ixz="0" iyy="10" iyz="0" izz="10"/>
    </inertial>
  </link>

  <link name="panel_link">
    <visual>
      <origin xyz="0 0 0" rpy="0 0 0"/>
      <geometry>
        <mesh filename="elevator_panel.dae" scale="1 1 1"/>
      </geometry>
    </visual>

    <collision>
      <origin xyz="0 0 0" rpy="0 0 0"/>
      <geometry>
        <box size="0.0 0.0 0.0"/>
      </geometry>
    </collision>

    <inertial>
      <origin xyz="0 0 0" rpy="0 0 0"/>
      <mass value="50.0"/>
      <inertia ixx="10" ixy="0" ixz="0" iyy="10" iyz="0" izz="10"/>
    </inertial>
  </link>

  <!-- =========================
       Buttons (static collision)
       ========================= -->
  <link name="button_0_0_link">
    <visual>
      <origin xyz="0 0 0" rpy="0 0 0"/>
      <geometry>
        <mesh filename="button_5.dae" scale="1 1 1"/>
      </geometry>
    </visual>

    <collision>
      <origin xyz="0 0 0" rpy="0 0 0"/>
      <geometry>
        <box size="0.19 0.02 0.09"/>
      </geometry>
    </collision>

    <inertial>
      <origin xyz="0 0 0" rpy="0 0 0"/>
      <mass value="0.1"/>
      <inertia ixx="0.001" ixy="0" ixz="0" iyy="0.001" iyz="0" izz="0.001"/>
    </inertial>
  </link>

  <joint name="button_0_0_joint" type="prismatic">
    <parent link="cabin_link"/>
    <child link="button_0_0_link"/>
    <origin xyz="-1.75 0.24119 1.625" rpy="0 0 0"/>
    <!-- Press direction: -Y -->
    <axis xyz="0 -1 0"/>
    <!-- 1 cm travel -->
    <limit lower="0.0" upper="0.01" effort="20" velocity="0.2"/>
  </joint>

  <link name="button_0_1_link">
    <visual>
      <origin xyz="0 0 0" rpy="0 0 0"/>
      <geometry>
        <mesh filename="button_6.dae" scale="1 1 1"/>
      </geometry>
    </visual>

    <collision>
      <origin xyz="0 0 0" rpy="0 0 0"/>
      <geometry>
        <box size="0.19 0.02 0.09"/>
      </geometry>
    </collision>

    <inertial>
      <origin xyz="0 0 0" rpy="0 0 0"/>
      <mass value="0.1"/>
      <inertia ixx="0.001" ixy="0" ixz="0" iyy="0.001" iyz="0" izz="0.001"/>
    </inertial>
  </link>

  <joint name="button_0_1_joint" type="prismatic">
    <parent link="cabin_link"/>
    <child link="button_0_1_link"/>
    <origin xyz="-1.97 0.24119 1.625" rpy="0 0 0"/>
    <!-- Press direction: -Y -->
    <axis xyz="0 -1 0"/>
    <!-- 1 cm travel -->
    <limit lower="0.0" upper="0.01" effort="20" velocity="0.2"/>
  </joint>

  <link name="button_1_0_link">
    <visual>
      <origin xyz="0 0 0" rpy="0 0 0"/>
      <geometry>
        <mesh filename="button_3.dae" scale="1 1 1"/>
      </geometry>
    </visual>

    <collision>
      <origin xyz="0 0 0" rpy="0 0 0"/>
      <geometry>
        <box size="0.19 0.02 0.09"/>
      </geometry>
    </collision>

    <inertial>
      <origin xyz="0 0 0" rpy="0 0 0"/>
      <mass value="0.1"/>
      <inertia ixx="0.001" ixy="0" ixz="0" iyy="0.001" iyz="0" izz="0.001"/>
    </inertial> 
  </link>

  <joint name="button_1_0_joint" type="prismatic">
    <parent link="cabin_link"/>
    <child link="button_1_0_link"/>
    <origin xyz="-1.75 0.24119 1.447" rpy="0 0 0"/>
    <!-- Press direction: -Y -->
    <axis xyz="0 -1 0"/>
    <!-- 1 cm travel -->
    <limit lower="0.0" upper="0.01" effort="20" velocity="0.2"/>
  </joint>

  <link name="button_1_1_link">
    <visual>
      <origin xyz="0 0 0" rpy="0 0 0"/>
      <geometry>
        <mesh filename="button_4.dae" scale="1 1 1"/>
      </geometry>
    </visual>

    <collision>
      <origin xyz="0 0 0" rpy="0 0 0"/>
      <geometry>
        <box size="0.19 0.02 0.09"/>
      </geometry>
    </collision>

    <inertial>
      <origin xyz="0 0 0" rpy="0 0 0"/>
      <mass value="0.1"/>
      <inertia ixx="0.001" ixy="0" ixz="0" iyy="0.001" iyz="0" izz="0.001"/>
    </inertial>
  </link>

  <joint name="button_1_1_joint" type="prismatic">
    <parent link="cabin_link"/>
    <child link="button_1_1_link"/>
    <origin xyz="-1.97 0.24119 1.447" rpy="0 0 0"/>
    <!-- Press direction: -Y -->
    <axis xyz="0 -1 0"/>
    <!-- 1 cm travel -->
    <limit lower="0.0" upper="0.01" effort="20" velocity="0.2"/>
  </joint>

  <link name="button_2_0_link">
    <visual>
      <origin xyz="0 0 0" rpy="0 0 0"/>
      <geometry>
        <mesh filename="button_ground.dae" scale="1 1 1"/>
      </geometry>
    </visual>

    <collision>
      <origin xyz="0 0 0" rpy="0 0 0"/>
      <geometry>
        <box size="0.19 0.02 0.09"/>
      </geometry>
    </collision>

    <inertial>
      <origin xyz="0 0 0" rpy="0 0 0"/>
      <mass value="0.1"/>
      <inertia ixx="0.001" ixy="0" ixz="0" iyy="0.001" iyz="0" izz="0.001"/>
    </inertial>
  </link>

  <joint name="button_2_0_joint" type="prismatic">
    <parent link="cabin_link"/>
    <child link="button_2_0_link"/>
    <origin xyz="-1.75 0.24119 1.269" rpy="0 0 0"/>
    <!-- Press direction: -Y -->
    <axis xyz="0 -1 0"/>
    <!-- 1 cm travel -->
    <limit lower="0.0" upper="0.01" effort="20" velocity="0.2"/>
  </joint>

  <link name="button_2_1_link">
    <visual>
      <origin xyz="0 0 0" rpy="0 0 0"/>
      <geometry>
        <mesh filename="button_2.dae" scale="1 1 1"/>
      </geometry>
    </visual>

    <collision>
      <origin xyz="0 0 0" rpy="0 0 0"/>
      <geometry>
        <box size="0.19 0.02 0.09"/>
      </geometry>
    </collision>

    <inertial>
      <origin xyz="0 0 0" rpy="0 0 0"/>
      <mass value="0.1"/>
      <inertia ixx="0.001" ixy="0" ixz="0" iyy="0.001" iyz="0" izz="0.001"/>
    </inertial>
  </link>

  <joint name="button_2_1_joint" type="prismatic">
    <parent link="cabin_link"/>
    <child link="button_2_1_link"/>
    <origin xyz="-1.97 0.24119 1.269" rpy="0 0 0"/>
    <!-- Press direction: -Y -->
    <axis xyz="0 -1 0"/>
    <!-- 1 cm travel -->
    <limit lower="0.0" upper="0.01" effort="20" velocity="0.2"/>
  </joint>

  <link name="button_3_0_link">
    <visual>
      <origin xyz="0 0 0" rpy="0 0 0"/>
      <geometry>
        <mesh filename="button_open.dae" scale="1 1 1"/>
      </geometry>
    </visual>

    <collision>
      <origin xyz="0 0 0" rpy="0 0 0"/>
      <geometry>
        <box size="0.19 0.02 0.09"/>
      </geometry>
    </collision>

    <inertial>
      <origin xyz="0 0 0" rpy="0 0 0"/>
      <mass value="0.1"/>
      <inertia ixx="0.001" ixy="0" ixz="0" iyy="0.001" iyz="0" izz="0.001"/>
    </inertial>
  </link>

  <joint name="button_3_0_joint" type="prismatic">
    <parent link="cabin_link"/>
    <child link="button_3_0_link"/>
    <origin xyz="-1.75 0.24119 1.091" rpy="0 0 0"/>
    <!-- Press direction: -Y -->
    <axis xyz="0 -1 0"/>
    <!-- 1 cm travel -->
    <limit lower="0.0" upper="0.01" effort="20" velocity="0.2"/>
  </joint>

  <link name="button_3_1_link">
    <visual>
      <origin xyz="0 0 0" rpy="0 0 0"/>
      <geometry>
        <mesh filename="button_close.dae" scale="1 1 1"/>
      </geometry>
    </visual>

    <collision>
      <origin xyz="0 0 0" rpy="0 0 0"/>
      <geometry>
        <box size="0.19 0.02 0.09"/>
      </geometry>
    </collision>

    <inertial>
      <origin xyz="0 0 0" rpy="0 0 0"/>
      <mass value="0.1"/>
      <inertia ixx="0.001" ixy="0" ixz="0" iyy="0.001" iyz="0" izz="0.001"/>
    </inertial>
  </link>

  <joint name="button_3_1_joint" type="prismatic">
    <parent link="cabin_link"/>
    <child link="button_3_1_link"/> 
    <origin xyz="-1.97 0.24119 1.091" rpy="0 0 0"/>
    <!-- Press direction: -Y -->
    <axis xyz="0 -1 0"/>
    <!-- 1 cm travel -->
    <limit lower="0.0" upper="0.01" effort="20" velocity="0.2"/>
  </joint>

</robot>